Workbook

Sheet Hướng dẫn
A1: PHIẾU THU THẬP MINH CHỨNG & CHẤM ĐIỂM CĐS (DBI)
A3: Ngân hàng | B3: BIDV | C3: ← Tên ngân hàng: KHÔNG sửa (code đọc ô B3 để nhận diện)
A4: Người phụ trách | B4: VLy
A5: Năm dữ liệu (FY) | B5: 2025
A6: Deadline nộp | B6: 09/10
A8: CÁCH ĐIỀN (sheet "Chấm điểm")
A9: 1. Chỉ điền vào các cột nền VÀNG (Level, Minh chứng, Nguồn, Trang, Năm, Ghi chú). Cột xám là cố định, không sửa.
A10: 2. Đọc mô tả Mức 1–5 ở các cột bên phải của từng tiêu chí, rồi đọc minh chứng đã ghi để chọn Level.
A11: 3. Level: chọn từ danh sách 1, 2, 3, 4, 5 hoặc N/A (không có minh chứng công khai). Không để trống.
A12: 4. Trả lời 3 câu hỏi: (a) có tồn tại không; (b) phạm vi: một phần / một cụm / toàn ngân hàng / cùng đối tác; (c) có số liệu hoặc cam kết đo lường không.
A13: 5. Minh chứng: ghi ngắn gọn điều ngân hàng đã làm, ưu tiên có số liệu. Không chép nguyên đoạn dài.
A14: 6. Nguồn: tên tài liệu hoặc URL. Nhiều nguồn thì cách nhau bằng dấu chấm phẩy ( ; ). Ưu tiên BCTN, BC PTBV, website ngân hàng hơn tin tức.
A15: 7. Trang: số trang trong tài liệu (nếu là website thì ghi "web"). Năm: năm của tài liệu/bài đăng.
A16: 8. Chỉ dùng dữ liệu công khai. Chấm theo minh chứng đã ghi, không chấm theo ấn tượng chung về ngân hàng.
A17: 9. Không thêm/xóa/đổi thứ tự dòng, không đổi tên cột, không đổi mã tiêu chí (phải đủ 140 mã).
A19: VÍ DỤ ĐIỀN (chỉ minh họa, KHÔNG chép vào sheet Chấm điểm)
A20: Mã | B20: Level | C20: Minh chứng | D20: Nguồn | E20: Trang | F20: Năm
A21: 1.1.1 | B21: 3 | C21: Ứng dụng gợi ý sản phẩm/ưu đãi theo hành vi giao dịch cho nhóm khách hàng cá nhân; chưa nêu phạm vi toàn ngân hàng. | D21: BCTN 2025; website mục Ngân hàng số | E21: 45 | F21: 2025
A22: 1.1.2 | B22: N/A | C22: Không tìm thấy thông tin công khai.
A25: TIẾN ĐỘ & KIỂM TRA TỰ ĐỘNG
A26: Trụ cột | B26: Tổng tiêu chí | C26: Đã có Level (1–5) | D26: N/A | E26: Còn trống
A27: 1. Trụ cột Khách hàng | B27: =COUNTIF('Chấm điểm'!$A$2:$A$141,A27) -> 25 | C27: =COUNTIFS('Chấm điểm'!$A$2:$A$141,A27,'Chấm điểm'!$E$2:$E$141,">=1",'Chấm điểm'!$E$2:$E$141,"<=5") -> 24 | D27: =COUNTIFS('Chấm điểm'!$A$2:$A$141,A27,'Chấm điểm'!$E$2:$E$141,"N/A") -> 1 | E27: =B27-C27-D27 -> 0
A28: 2. Trụ cột Chiến lược | B28: =COUNTIF('Chấm điểm'!$A$2:$A$141,A28) -> 24 | C28: =COUNTIFS('Chấm điểm'!$A$2:$A$141,A28,'Chấm điểm'!$E$2:$E$141,">=1",'Chấm điểm'!$E$2:$E$141,"<=5") -> 23 | D28: =COUNTIFS('Chấm điểm'!$A$2:$A$141,A28,'Chấm điểm'!$E$2:$E$141,"N/A") -> 1 | E28: =B28-C28-D28 -> 0
A29: 3. Trụ cột Công nghệ | B29: =COUNTIF('Chấm điểm'!$A$2:$A$141,A29) -> 29 | C29: =COUNTIFS('Chấm điểm'!$A$2:$A$141,A29,'Chấm điểm'!$E$2:$E$141,">=1",'Chấm điểm'!$E$2:$E$141,"<=5") -> 19 | D29: =COUNTIFS('Chấm điểm'!$A$2:$A$141,A29,'Chấm điểm'!$E$2:$E$141,"N/A") -> 10 | E29: =B29-C29-D29 -> 0
A30: 4. Trụ cột Vận hành | B30: =COUNTIF('Chấm điểm'!$A$2:$A$141,A30) -> 22 | C30: =COUNTIFS('Chấm điểm'!$A$2:$A$141,A30,'Chấm điểm'!$E$2:$E$141,">=1",'Chấm điểm'!$E$2:$E$141,"<=5") -> 14 | D30: =COUNTIFS('Chấm điểm'!$A$2:$A$141,A30,'Chấm điểm'!$E$2:$E$141,"N/A") -> 8 | E30: =B30-C30-D30 -> 0
A31: 5. Trụ cột Văn hóa | B31: =COUNTIF('Chấm điểm'!$A$2:$A$141,A31) -> 22 | C31: =COUNTIFS('Chấm điểm'!$A$2:$A$141,A31,'Chấm điểm'!$E$2:$E$141,">=1",'Chấm điểm'!$E$2:$E$141,"<=5") -> 19 | D31: =COUNTIFS('Chấm điểm'!$A$2:$A$141,A31,'Chấm điểm'!$E$2:$E$141,"N/A") -> 3 | E31: =B31-C31-D31 -> 0
A32: 6. Trụ cột Dữ liệu | B32: =COUNTIF('Chấm điểm'!$A$2:$A$141,A32) -> 18 | C32: =COUNTIFS('Chấm điểm'!$A$2:$A$141,A32,'Chấm điểm'!$E$2:$E$141,">=1",'Chấm điểm'!$E$2:$E$141,"<=5") -> 10 | D32: =COUNTIFS('Chấm điểm'!$A$2:$A$141,A32,'Chấm điểm'!$E$2:$E$141,"N/A") -> 8 | E32: =B32-C32-D32 -> 0
A33: TỔNG | B33: =SUM(B27:B32) -> 140 | C33: =SUM(C27:C32) -> 109 | D33: =SUM(D27:D32) -> 31 | E33: =SUM(E27:E32) -> 0
A35: Level sai (khác 1–5 và N/A) | D35: =COUNTA('Chấm điểm'!$E$2:$E$141)-COUNT('Chấm điểm'!$E$2:$E$141)-COUNTIF('Chấm điểm'!$E$2:$E$141,"N/A")+COUNT('Chấm điểm'!$E$2:$E$141)-COUNTIFS('Chấm điểm'!$E$2:$E$141,">=1",'Chấm điểm'!$E$2:$E$141,"<=5") -> 0
A36: Có Level 1–5 nhưng thiếu Minh chứng | D36: =SUMPRODUCT(ISNUMBER('Chấm điểm'!$E$2:$E$141)*('Chấm điểm'!$F$2:$F$141="")) -> 0
A37: Có Level 1–5 nhưng thiếu Nguồn | D37: =SUMPRODUCT(ISNUMBER('Chấm điểm'!$E$2:$E$141)*('Chấm điểm'!$G$2:$G$141="")) -> 0
A38: Mục tiêu: "Còn trống" = 0 và cả 3 ô kiểm tra = 0 trước khi nộp.

Sheet Chấm điểm
A1: Trụ cột | B1: Nhóm tiêu chí | C1: Mã | D1: Tiêu chí | E1: Level | F1: Minh chứng | G1: Nguồn | H1: Trang | I1: Năm | J1: Ghi chú | K1: Mức 1 | L1: Mức 2 | M1: Mức 3 | N1: Mức 4 | O1: Mức 5
A2: 1. Trụ cột Khách hàng | B2: Góc nhìn của khách hàng đối với sản phẩm, dịch vụ | C2: 1.1.1 | D2: Cá nhân hóa trải nghiệm | E2: 3 | F2: SmartBanking X (07/2025) dùng AI/ML phân tích chi tiêu, dự đoán hành vi và gợi ý tính năng/ưu đãi theo nhu cầu; hai giao diện Pearl X/Emerald X (Emerald có hỗ trợ cá nhân 1:1); giải Sao Khuê 2025 cho tài khoản số đẹp cá nhân hóa dựa trên dữ liệu khách hàng. | G2: BIDV, Báo cáo thường niên 2025 (bidv.com.vn - Quan hệ nhà đầu tư); thitruongtaichinhtiente.vn, 'BIDV SmartBanking phiên bản X - dấu ấn tiên phong cùng loạt tính năng mới' (07/2025) | H2: 12-13; 84-85 | I2: 2025 | J2: Độ tin cậy: TB. Chưa có chỉ số đo mức độ cá nhân hóa toàn ngân hàng. | K2: Có ít hoặc chưa có cá nhân hóa trong trải nghiệm khách hàng. | L2: Một số khía cạnh trong trải nghiệm khách hàng được cá nhân hóa dựa trên thông tin về khách hàng thu thập được ở một số bộ phận, đơn vị chức năng. | M2: Một số khía cạnh trong trải nghiệm khách hàng được cá nhân hóa dựa trên thông tin về khách hàng thu thập được và triển khai ở một số cụm các bộ phận, đơn vị chức năng. | N2: Tất cả các khía cạnh trong trải nghiệm khách hàng được cá nhân hóa dựa trên thông tin về khách hàng thu thập được và triển khai trong toàn doanh nghiệp. | O2: Tất cả các khía cạnh trong trải nghiệm khách hàng được cá nhân hóa dựa trên thông tin về khách hàng thu thập được, triển khai trong toàn doanh nghiệp và các đối tác trong hệ sinh thái của doanh nghiệp.
A3: 1. Trụ cột Khách hàng | B3: Góc nhìn của khách hàng đối với sản phẩm, dịch vụ | C3: 1.1.2 | D3: Tiếp thị mục tiêu | E3: 3 | F3: SmartBanking X gợi ý ưu đãi theo nhu cầu; cán bộ dùng CRM và Daily Dashboard quản lý danh mục khách hàng theo phân khúc; AI hỗ trợ tư vấn. | G3: BIDV, Báo cáo thường niên 2025 (bidv.com.vn - Quan hệ nhà đầu tư); thitruongtaichinhtiente.vn, 'BIDV SmartBanking phiên bản X - dấu ấn tiên phong cùng loạt tính năng mới' (07/2025) | H3: 84-85; 98-99 | I3: 2025 | J3: Độ tin cậy: TB. Chưa có số liệu hiệu quả tiếp thị nhắm mục tiêu. | K3: Có một số nội dung tiếp thị được nhắm mục tiêu. | L3: Hầu hết nội dung tiếp thị được nhắm mục tiêu. | M3: Hầu hết nội dung tiếp thị được nhắm mục tiêu và có liên quan đến bối cảnh của khách hàng. | N3: Tất cả nội dung tiếp thị trong doanh nghiệp được nhắm mục tiêu và có liên quan đến bối cảnh của khách hàng. | O3: Tất cả nội dung tiếp thị từ cả doanh nghiệp và các đối tác trong hệ sinh thái của doanh nghiệp đều được nhắm mục tiêu và có liên quan đến bối cảnh của khách hàng.
A4: 1. Trụ cột Khách hàng | B4: Góc nhìn của khách hàng đối với sản phẩm, dịch vụ | C4: 1.1.3 | D4: Tự tùy chỉnh | E4: 3 | F4: SmartBanking X kiến trúc Plug & Play, tự phục vụ: đầu tư tự động, vay ứng lương, mở thẻ online, quản lý tài chính, quản lý chứng khoán; chọn giao diện Pearl/Emerald. | G4: BIDV, Báo cáo thường niên 2025 (bidv.com.vn - Quan hệ nhà đầu tư); thitruongtaichinhtiente.vn, 'BIDV SmartBanking phiên bản X - dấu ấn tiên phong cùng loạt tính năng mới' (07/2025) | H4: 12-13 | I4: 2025 | J4: Độ tin cậy: TB. | K4: Có rất ít công cụ sẵn có để cho phép khách hàng tùy chỉnh sản phẩm và dịch vụ. | L4: Một số công cụ có sẵn để cho phép khách hàng tùy chỉnh một số sản phẩm và dịch vụ. | M4: Một loạt các công cụ có sẵn để cho phép khách hàng tùy chỉnh tương đối đầy đủ cho một số sản phẩm và dịch vụ. | N4: Một loạt các công cụ được doanh nghiệp cung cấp cho phép khách hàng tùy chỉnh hoàn toàn cho các sản phẩm và dịch vụ của chính họ cùng một lúc. | O4: Một loạt các công cụ được doanh nghiệp và các đối tác trong hệ sinh thái của doanh nghiệp cung cấp cho phép khách hàng tùy chỉnh đầy đủ cho tất cả các sản phẩm và dịch vụ cùng một lúc.
A5: 1. Trụ cột Khách hàng | B5: Góc nhìn của khách hàng đối với sản phẩm, dịch vụ | C5: 1.1.4 | D5: Dễ sử dụng | E5: 3 | F5: Điểm chất lượng dịch vụ tổng thể gần 97; hệ thống IT vận hành thông suốt khi khối lượng giao dịch tăng 1,5 lần; SmartBanking X làm mới giao diện (07/2025). | G5: BIDV, Báo cáo thường niên 2025 (bidv.com.vn - Quan hệ nhà đầu tư); thitruongtaichinhtiente.vn, 'BIDV SmartBanking phiên bản X - dấu ấn tiên phong cùng loạt tính năng mới' (07/2025) | H5: 84-85; 98-99 | I5: 2025 | J5: Độ tin cậy: TB. Chưa có chỉ số riêng về mức độ dễ dàng (CES) nên giữ 3. | K5: Có rất ít hoạt động tương tác với doanh nghiệp khiến khách hàng cảm thấy dễ dàng được đáp ứng nhu cầu cá nhân. | L5: Một số tương tác với doanh nghiệp khiến khách hàng cảm thấy dễ dàng được đáp ứng nhu cầu cá nhân. | M5: Hầu hết các tương tác với doanh nghiệp khiến khách hàng cảm thấy dễ dàng được đáp ứng nhu cầu cá nhân. | N5: Tất cả các tương tác với doanh nghiệp khiến khách hàng cảm thấy dễ dàng được đáp ứng nhu cầu cá nhân. | O5: Tất cả các tương tác với doanh nghiệp và các đối tác trong hệ sinh thái của doanh nghiệp khiến khách hàng cảm thấy dễ dàng được đáp ứng nhu cầu cá nhân.
A6: 1. Trụ cột Khách hàng | B6: Góc nhìn của khách hàng đối với sản phẩm, dịch vụ | C6: 1.1.5 | D6: Mức độ hứng thú của khách hàng | E6: 3 | F6: NPS 76,7% phản ánh mức độ gắn kết tích cực, xu hướng duy trì quan hệ lâu dài của khách hàng. | G6: BIDV, Báo cáo thường niên 2025 (bidv.com.vn - Quan hệ nhà đầu tư) | H6: 84-85 | I6: 2025 | J6: Độ tin cậy: Thấp. NPS dùng làm chỉ báo gián tiếp. | K6: Có rất ít hoạt động tương tác của khách hàng với doanh nghiệp khiến khách hàng cảm thấy thú vị. | L6: Một số hoạt động tương tác của khách hàng với doanh nghiệp khiến khách hàng cảm thấy thú vị. | M6: Hầu hết hoạt động tương tác của khách hàng với doanh nghiệp khiến khách hàng cảm thấy thú vị. | N6: Tất cả hoạt động tương tác của khách hàng với doanh nghiệp khiến khách hàng cảm thấy thú vị. | O6: Tất cả hoạt động tương tác của khách hàng với doanh nghiệp và các đối tác trong hệ sinh thái của doanh nghiệp khiến khách hàng cảm thấy thú vị.
A7: 1. Trụ cột Khách hàng | B7: Góc nhìn của khách hàng đối với sản phẩm, dịch vụ | C7: 1.1.6 | D7: Tương tác số | E7: 3 | F7: 96% giao dịch tài chính khách hàng cá nhân và 56% khách hàng tổ chức qua kênh số; ~12 triệu người dùng SmartBanking; BCTN nêu đại đa số sản phẩm dịch vụ đã số hóa toàn trình. | G7: thitruongtaichinhtiente.vn, 'BIDV tiên phong với chiến lược kép: số hóa - xanh hóa' (10/2025); BIDV, Báo cáo thường niên 2025 (bidv.com.vn - Quan hệ nhà đầu tư) | H7: 88-89 | I7: 2025 | J7: Độ tin cậy: Cao. Tỷ lệ khách hàng tổ chức mới 56% nên chấm 3. | K7: Có rất ít tương tác có thể được thực hiện trên các kênh số. | L7: Một số tương tác của khách hàng với doanh nghiệp có thể được thực hiện trên các kênh số. | M7: Hầu hết các tương tác của khách hàng với doanh nghiệp có thể được thực hiện trên các kênh số. | N7: Tất cả các tương tác của khách hàng với doanh nghiệp có thể được thực hiện trên các kênh số. | O7: Tất cả các tương tác của khách hàng với doanh nghiệp và các đối tác trong hệ sinh thái của doanh nghiệp có thể được thực hiện trên các kênh số.
A8: 1. Trụ cột Khách hàng | B8: Góc nhìn của khách hàng đối với sản phẩm, dịch vụ | C8: 1.1.7 | D8: Chủ động chăm sóc | E8: 3 | F8: SmartBanking X dùng AI/ML phát hiện sớm và cảnh báo giao dịch nghi ngờ; truyền thông cảnh báo rủi ro gian lận cho khách hàng. | G8: thitruongtaichinhtiente.vn, 'BIDV SmartBanking phiên bản X - dấu ấn tiên phong cùng loạt tính năng mới' (07/2025); BIDV, Báo cáo thường niên 2025 (bidv.com.vn - Quan hệ nhà đầu tư) | H8: 84-85 | I8: 2025 | J8: Độ tin cậy: TB. | K8: Có rất ít nhu cầu hoặc vấn đề của khách hàng được doanh nghiệp dự đoán trước. | L8: Một số nhu cầu hoặc vấn đề của khách hàng được doanh nghiệp dự đoán trước. | M8: Hầu hết các nhu cầu hoặc vấn đề của khách hàng đều được doanh nghiệp dự đoán trước. | N8: Tất cả các nhu cầu hoặc vấn đề của khách hàng đều được doanh nghiệp dự đoán trước. | O8: Tất cả các nhu cầu hoặc vấn đề của khách hàng đều được doanh nghiệp hoặc các đối tác trong hệ sinh thái của doanh nghiệp dự đoán trước.
A9: 1. Trụ cột Khách hàng | B9: Góc nhìn của khách hàng đối với sản phẩm, dịch vụ | C9: 1.1.8 | D9: Gắn kết xã hội | E9: 2 | F9: Hàng trăm chương trình an sinh xã hội; khoảng 200 kiosk y tế thông minh; truyền thông hướng dẫn khách hàng sử dụng dịch vụ an toàn. | G9: BIDV, Báo cáo thường niên 2025 (bidv.com.vn - Quan hệ nhà đầu tư) | H9: 78-79; 84-85 | I9: 2025 | J9: Độ tin cậy: Thấp. Là hoạt động cộng đồng, chưa phải gắn kết xã hội giữa khách hàng. | K9: Sự gắn kết xã hội chưa được xem xét. | L9: Ít nhất một đơn vị bộ phận, đơn vị chức năng có hoạt động thúc đẩy sự gắn kết xã hội với và giữa các khách hàng để khuyến khích sự trung thành. | M9: Hầu hết các đơn vị bộ phận, đơn vị chức năng có hoạt động thúc đẩy sự gắn kết xã hội với và giữa các khách hàng để khuyến khích sự trung thành. | N9: Toàn bộ các đơn vị bộ phận, đơn vị chức năng có hoạt động thúc đẩy sự gắn kết xã hội với và giữa các khách hàng để khuyến khích sự trung thành. | O9: Toàn bộ các đơn vị bộ phận, đơn vị chức năng của doanh nghiệp và các đối tác trong hệ sinh thái có hoạt động thúc đẩy sự gắn kết xã hội với và giữa các khách hàng để khuyến khích sự trung thành.
A10: 1. Trụ cột Khách hàng | B10: Góc nhìn của khách hàng đối với sản phẩm, dịch vụ | C10: 1.1.9 | D10: Thúc đẩy mức độ trung thành | E10: 2 | F10: NPS đạt 83,1%; mục tiêu ESG 2030: NPS nằm trong top 10 thương hiệu có trải nghiệm tốt nhất VN. Chưa thấy chương trình thúc đẩy trung thành cụ thể. | G10: BIDV, Báo cáo phát triển bền vững 2025 | H10: 10-11 | I10: 2025 | K10: Các chương trình thúc đẩy sự trung thành chưa được doanh nghiệp tích cực xem xét. | L10: Doanh nghiệp khuyến khích toàn bộ các bộ phận, đơn vị chức năng có liên quan đến khách hàng triển khai các hành động để thúc đẩy sự trung thành của khách hàng với thương hiệu. | M10: Một số bộ phận, đơn vị chức năng có hành động thực tế thúc đẩy sự trung thành của khách hàng với thương hiệu. | N10: Toàn bộ các bộ phận, đơn vị chức năng liên quan đến khách hàng có hành động thực tế thúc đẩy sự trung thành của khách hàng với thương hiệu. | O10: Toàn bộ các bộ phận, đơn vị chức năng liên quan đến khách hàng và hệ sinh thái có hành động thực tế thúc đẩy sự trung thành của khách hàng với thương hiệu.
A11: 1. Trụ cột Khách hàng | B11: Quản lý trải nghiệm khách hàng | C11: 1.2.1 | D11: Tầm nhìn về trải nghiệm khách hàng | E11: 4 | F11: BIDV 'kiên định định hướng lấy khách hàng làm trọng tâm', coi chăm sóc và bảo vệ quyền lợi khách hàng là nền tảng; quản lý trải nghiệm theo hướng lắng nghe chủ động, phản hồi kịp thời, cải tiến liên tục; định vị 'Thân thiện - Hiện đại - Nghĩa tình'. | G11: BIDV, Báo cáo thường niên 2025 (bidv.com.vn - Quan hệ nhà đầu tư) | H11: 82-85; 90-91 | I11: 2025 | J11: Độ tin cậy: Cao. | K11: Doanh nghiệp chưa có bất kỳ tầm nhìn về trải nghiệm khách hàng. | L11: Một số bộ phận, đơn vị chức năng đã bắt đầu xác định tầm nhìn về trải nghiệm của khách hàng. | M11: Doanh nghiệp có một tầm nhìn về trải nghiệm khách hàng được xác định rõ ràng, được một số bộ phận, đơn vị chức năng áp dụng. | N11: Doanh nghiệp có tầm nhìn chung về trải nghiệm khách hàng được xác định rõ ràng và dễ hiểu. | O11: Doanh nghiệp và các đối tác trong hệ sinh thái của doanh nghiệp có tầm nhìn chung về trải nghiệm khách hàng được xác định rõ ràng và dễ hiểu.
A12: 1. Trụ cột Khách hàng | B12: Quản lý trải nghiệm khách hàng | C12: 1.2.2 | D12: Thiết kế theo định hướng của trải nghiệm khách hàng | E12: 3 | F12: Dự án chuyển đổi toàn diện ngân hàng bán lẻ thực thi theo chuẩn tư vấn quốc tế; cán bộ dùng CRM, Daily Dashboard; Contact Center đa kênh hợp nhất hướng tới trải nghiệm nhất quán. | G12: BIDV, Báo cáo thường niên 2025 (bidv.com.vn - Quan hệ nhà đầu tư) | H12: 84-85; 98-99 | I12: 2025 | J12: Độ tin cậy: TB. | K12: Trải nghiệm khách hàng chưa được xem xét một cách có chủ ý. | L12: Trải nghiệm khách hàng được xem xét bởi ít nhất một bộ phận, đơn vị chức năng của doanh nghiệp trong việc thiết kế và triển khai các sản phẩm và dịch vụ. | M12: Trải nghiệm khách hàng được xem xét bởi hầu hết các bộ phận, đơn vị chức năng của doanh nghiệp trong việc thiết kế và triển khai các sản phẩm và dịch vụ. | N12: Trải nghiệm khách hàng được doanh nghiệp xem xét đầy đủ trong thiết kế và triển khai các sản phẩm và dịch vụ. | O12: Trải nghiệm của khách hàng được doanh nghiệp và các đối tác trong hệ sinh thái của doanh nghiệp xem xét đầy đủ trong quá trình thiết kế và triển khai các sản phẩm và dịch vụ.
A13: 1. Trụ cột Khách hàng | B13: Quản lý trải nghiệm khách hàng | C13: 1.2.3 | D13: Có ngân sách đầu tư để đạt các mục tiêu trải nghiệm khách hàng | E13: N/A | F13: Không tìm thấy thông tin công khai. | J13: Chưa tách ngân sách trải nghiệm khách hàng. | K13: Doanh nghiệp chưa có kế hoạch đầu tư để đạt được tầm nhìn trải nghiệm của khách hàng. | L13: Ít nhất một đơn vị bộ phận, đơn vị chức năng trong doanh nghiệp lên kế hoạch đầu tư để đạt được tầm nhìn trải nghiệm khách hàng của mình. | M13: Hầu hết các bộ phận, đơn vị chức năng trong doanh nghiệp đều lên kế hoạch đầu tư để đạt được tầm nhìn về trải nghiệm khách hàng của họ. | N13: Toàn bộ bộ phận, đơn vị chức năng có liên quan đến khách hàng có kế hoạch đầu tư để đạt được tầm nhìn về trải nghiệm của khách hàng. | O13: Toàn bộ bộ phận, đơn vị chức năng có liên quan đến khách hàng và hệ sinh thái có kế hoạch đầu tư để đạt được tầm nhìn về trải nghiệm của khách hàng.
A14: 1. Trụ cột Khách hàng | B14: Quản lý trải nghiệm khách hàng | C14: 1.2.4 | D14: Phạm vi danh mục sản phẩm và dịch vụ | E14: 4 | F14: Danh mục số: SmartBanking X, BIDV Direct (ngân hàng số mới cho doanh nghiệp), MyShop Pro, Etax Mobile, thanh toán Cổng dịch vụ công quốc gia; hơn 40 giải thưởng 2025 (Ngân hàng bán lẻ tốt nhất VN, 7 giải Sao Khuê). | G14: BIDV, Báo cáo thường niên 2025 (bidv.com.vn - Quan hệ nhà đầu tư); thitruongtaichinhtiente.vn, 'BIDV triển khai nhiệm vụ kinh doanh năm 2026' (Etax Mobile, MyShop Pro) | H14: 12-15; 88-91 | I14: 2025 | J14: Độ tin cậy: TB. | K14: Trải nghiệm khách hàng chưa được xem xét trong phát triển danh mục sản phẩm và dịch vụ. | L14: Trải nghiệm khách hàng là một phần của danh mục sản phẩm và dịch vụ được cung cấp bởi ít nhất một bộ phận, đơn vị chức năng. | M14: Trải nghiệm khách hàng là một phần không thể thiếu trong danh mục sản phẩm và dịch vụ được cung cấp bởi hầu hết các bộ phận, đơn vị chức năng. | N14: Trải nghiệm khách hàng là một phần không thể thiếu trong danh mục sản phẩm và dịch vụ do doanh nghiệp cung cấp. | O14: Trải nghiệm của khách hàng là một phần không thể thiếu trong danh mục sản phẩm và dịch vụ do doanh nghiệp và các đối tác trong hệ sinh thái của doanh nghiệp cung cấp.
A15: 1. Trụ cột Khách hàng | B15: Quản lý trải nghiệm khách hàng | C15: 1.2.5 | D15: Quá trình đăng ký sử dụng sản phẩm và dịch vụ | E15: 3 | F15: Định danh điện tử cho khách hàng tổ chức (Sao Khuê 2025); mở thẻ online, vay ứng lương tự động trên SmartBanking; đăng ký bằng eKYC. | G15: BIDV, Báo cáo thường niên 2025 (bidv.com.vn - Quan hệ nhà đầu tư); thitruongtaichinhtiente.vn, 'BIDV SmartBanking phiên bản X - dấu ấn tiên phong cùng loạt tính năng mới' (07/2025) | H15: 12-13 | I15: 2025 | J15: Độ tin cậy: TB. | K15: Trải nghiệm của khách hàng chưa được đưa vào quá trình tiếp cận và giới thiệu đăng ký sản phẩm và dịch vụ cho khách hàng mới. | L15: Có ít nhất một bộ phận, đơn vị chức năng đưa trải nghiệm khách hàng vào quá trình tiếp cận và giới thiệu đăng ký sản phẩm và dịch vụ dành cho khách hàng mới. | M15: Hầu hết các bộ phận, đơn vị chức năng đưa trải nghiệm khách hàng vào quá trình tiếp cận và giới thiệu đăng ký sản phẩm và dịch vụ dành cho khách hàng mới. | N15: Toàn bộ doanh nghiệp đưa trải nghiệm khách hàng vào quá trình tiếp cận và giới thiệu đăng ký sản phẩm và dịch vụ dành cho khách hàng mới. | O15: Toàn bộ doanh nghiệp và hệ sinh thái của doanh nghiệp đưa trải nghiệm khách hàng được đưa vào quá trình tiếp cận và giới thiệu đăng ký sản phẩm và dịch vụ dành cho khách hàng mới.
A16: 1. Trụ cột Khách hàng | B16: Quản lý trải nghiệm khách hàng | C16: 1.2.6 | D16: Đa kênh hợp nhất | E16: 3 | F16: Contact Center đa kênh hợp nhất, trải nghiệm hỗ trợ nhất quán trên mọi kênh; Chatbot mở rộng trên nền tảng ngân hàng số cho cả khách hàng doanh nghiệp. | G16: BIDV, Báo cáo thường niên 2025 (bidv.com.vn - Quan hệ nhà đầu tư) | H16: 84-85 | I16: 2025 | J16: Độ tin cậy: TB. BCTN dùng 'từng bước hoàn thiện' nên chấm 3. | K16: Khách hàng chưa thể bắt đầu hành trình trên một kênh/thiết bị và tiếp tục ở một kênh/thiết bị khác. | L16: Doanh nghiệp quản lý được bối cảnh của một số cấu phần trong hành trình khách hàng liên thông trên hầu hết các kênh và thiết bị. | M16: Doanh nghiệp quản lý được bối cảnh của hầu hết các hành trình khách hàng liên thông trên hầu hết các kênh và thiết bị. | N16: Doanh nghiệp quản lý được bối cảnh của toàn bộ các hành trình khách hàng liên thông trên tất cả các kênh và thiết bị. | O16: Doanh nghiệp và hệ sinh thái quản lý được bối cảnh của toàn bộ các hành trình khách hàng liên thông trên tất cả các kênh và thiết bị.
A17: 1. Trụ cột Khách hàng | B17: Quản lý trải nghiệm khách hàng | C17: 1.2.7 | D17: Đo lường trải nghiệm khách hàng | E17: 3 | F17: Khảo sát quy mô lớn trên mọi kênh (chi nhánh, tổng đài, kênh số); điểm chất lượng dịch vụ ~97, NPS 76,7%; phản hồi chưa hài lòng được xử lý ưu tiên và dùng để cải tiến. | G17: BIDV, Báo cáo thường niên 2025 (bidv.com.vn - Quan hệ nhà đầu tư) | H17: 84-85 | I17: 2025 | J17: Độ tin cậy: TB. Chưa nêu quy mô mẫu. | K17: Hiệu suất hành trình khách hàng chưa được đo lường. | L17: Doanh nghiệp đo lường được hiệu quả của ít nhất một hành trình khách hàng và một số giai đoạn riêng lẻ trong hành trình của khách hàng. (Lưu ý: không phải khách hàng nào cũng đi đầy đủ toàn bộ hành trình, có một số khách hàng chỉ tham gia một vài giai đoạn trong hành trình khách hàng rồi kết thúc.) | M17: Doanh nghiệp đo lường được hiệu quả của tất cả hành trình khách hàng và một số giai đoạn riêng lẻ trong hành trình của khách hàng. | N17: Doanh nghiệp đo lường được hiệu quả của tất cả hành trình khách hàng và các giai đoạn riêng lẻ trong hành trình của khách hàng. | O17: Doanh nghiệp và hệ sinh thái đo lường được hiệu quả của tất cả hành trình khách hàng và các giai đoạn riêng lẻ trong hành trình của khách hàng.
A18: 1. Trụ cột Khách hàng | B18: Quản lý trải nghiệm khách hàng | C18: 1.2.8 | D18: Quản lý hành trình khách hàng | E18: 3 | F18: Quản lý trải nghiệm theo vòng lặp lắng nghe - phản hồi - cải tiến; phân tích tương tác bằng AI giúp nhận diện sai lệch trong tư vấn. | G18: BIDV, Báo cáo thường niên 2025 (bidv.com.vn - Quan hệ nhà đầu tư) | H18: 84-85 | I18: 2025 | J18: Độ tin cậy: Thấp. Chưa có bản đồ hành trình khách hàng được công bố. | K18: Hiệu suất của hành trình của khách hàng chưa được quản lý. | L18: Doanh nghiệp quản lý được hiệu quả của ít nhất một hành trình khách hàng và một số giai đoạn riêng lẻ trong hành trình của khách hàng. (Lưu ý: không phải khách hàng nào cũng đi đầy đủ toàn bộ hành trình, có một số khách hàng chỉ tham gia một vài giai đoạn trong hành trình khách hàng rồi kết thúc.) | M18: Doanh nghiệp quản lý được hiệu quả của tất cả hành trình khách hàng và một số giai đoạn riêng lẻ trong hành trình của khách hàng. | N18: Doanh nghiệp quản lý được hiệu quả của tất cả hành trình khách hàng và các giai đoạn riêng lẻ trong hành trình của khách hàng. | O18: Doanh nghiệp và hệ sinh thái quản lý được hiệu quả của tất cả hành trình khách hàng và các giai đoạn riêng lẻ trong hành trình của khách hàng.
A19: 1. Trụ cột Khách hàng | B19: Thấu hiểu khách hàng | C19: 1.3.1 | D19: Góc nhìn 360 độ về khách hàng | E19: 3 | F19: Chuyển đổi bán lẻ: quản lý theo phân khúc, CRM, Daily Dashboard, ứng dụng công nghệ và dữ liệu lớn trong kinh doanh. | G19: BIDV, Báo cáo thường niên 2025 (bidv.com.vn - Quan hệ nhà đầu tư) | H19: 88-89; 98-99 | I19: 2025 | J19: Độ tin cậy: TB. | K19: Doanh nghiệp chưa có góc nhìn 360 độ về khách hàng. | L19: Doanh nghiệp duy trì góc nhìn 360 độ của một số khách hàng. | M19: Doanh nghiệp duy trì góc nhìn 360 độ của hầu hết khách hàng. | N19: Doanh nghiệp luôn duy trì góc nhìn 360 độ về tất cả khách hàng. | O19: Doanh nghiệp và các đối tác trong hệ sinh thái của mình luôn duy trì góc nhìn 360 độ về tất cả khách hàng.
A20: 1. Trụ cột Khách hàng | B20: Thấu hiểu khách hàng | C20: 1.3.2 | D20: Nguồn khai thác dữ liệu tin cậy duy nhất | E20: 2 | F20: Core Banking Profile (go-live 03/09/2023) tích hợp hàng trăm ứng dụng; nghiên cứu học thuật ghi nhận hạn chế về đồng bộ dữ liệu. | G20: BIDV, Báo cáo thường niên 2025 (bidv.com.vn - Quan hệ nhà đầu tư); FIS Global, BIDV Client Story (core banking Profile); The Asian Banker, 'Best Core Banking Technology Implementation in Vietnam 2024' (bidv.com.vn); nghiencuu.tapchikinhtetaichinh.vn, 'Thực trạng chuyển đổi số và ứng dụng AI tại BIDV và một số đề xuất kiến nghị' | H20: 20-21 | I20: 2024 | J20: Độ tin cậy: Thấp. | K20: Doanh nghiệp chưa có một nguồn tin cậy duy nhất cho bất kỳ thông tin nào của khách hàng. | L20: Có một nguồn tin cậy duy nhất cho một số yếu tố của thông tin khách hàng trong toàn doanh nghiệp. | M20: Có một nguồn tin cậy duy nhất cho hầu hết các yếu tố thông tin khách hàng trong toàn doanh nghiệp. | N20: Có một nguồn tin cậy duy nhất cho toàn bộ thông tin khách hàng trong toàn doanh nghiệp. | O20: Có một nguồn tin cậy duy nhất cho toàn bộ thông tin khách hàng trong toàn doanh nghiệp và các đối tác trong hệ sinh thái của doanh nghiệp.
A21: 1. Trụ cột Khách hàng | B21: Thấu hiểu khách hàng | C21: 1.3.3 | D21: Nhu cầu của khách hàng | E21: 3 | F21: Phân tích tương tác khách hàng bằng AI, công cụ hỗ trợ tư vấn; khảo sát quy mô lớn để hiểu kỳ vọng; quản lý theo phân khúc. | G21: BIDV, Báo cáo thường niên 2025 (bidv.com.vn - Quan hệ nhà đầu tư) | H21: 84-85; 98-99 | I21: 2025 | J21: Độ tin cậy: TB. | K21: Kỳ vọng, sở thích và những điều khách hàng chưa hài lòng chưa được tích cực xem xét. | L21: Kỳ vọng, sở thích và những điều khách hàng chưa hài lòng tích cực xem xét ở một số bộ phận, đơn vị chức năng. | M21: Kỳ vọng, sở thích và những điều khách hàng chưa hài lòng được tích cực xem xét trên hầu hết các bộ phận, đơn vị chức năng. | N21: Tất cả các kỳ vọng, sở thích và những điều khách hàng chưa hài lòng đều được tích cực xem xét trong toàn doanh nghiệp. | O21: Tất cả các kỳ vọng, sở thích và những điều khách hàng chưa hài lòng đều được tích cực xem xét trong toàn doanh nghiệp và các đối tác trong hệ sinh thái của doanh nghiệp.
A22: 1. Trụ cột Khách hàng | B22: Niềm tin của khách hàng | C22: 1.4.1 | D22: Cam kết thương hiệu | E22: 2 | F22: Giá trị cốt lõi (Trí tuệ, Niềm tin, Chính trực, Tận tâm, Năng động); sứ mệnh mang lại lợi ích và tiện ích tốt nhất cho KH. | G22: BIDV, Báo cáo thường niên 2025 | H22: 22-23 | I22: 2025 | K22: Cam kết về thương hiệu hiếm khi phù hợp với kỳ vọng của khách hàng. | L22: Một số bộ phận, đơn vị chức năng (có liên quan đến cam kết thương hiệu) trong doanh nghiệp đáp ứng các kỳ vọng của khách hàng phù hợp với cam kết thương hiệu của doanh nghiệp. | M22: Hầu hết bộ phận, đơn vị chức năng (có liên quan đến cam kết thương hiệu) trong doanh nghiệp đáp ứng các kỳ vọng của khách hàng phù hợp với cam kết thương hiệu của doanh nghiệp. | N22: Toàn bộ các bộ phận, đơn vị chức năng (có liên quan đến cam kết thương hiệu) trong doanh nghiệp đáp ứng các kỳ vọng của khách hàng phù hợp với cam kết thương hiệu của doanh nghiệp. | O22: Toàn bộ các bộ phận, đơn vị chức năng (có liên quan đến cam kết thương hiệu) trong doanh nghiệp và hệ sinh thái doanh nghiệp đáp ứng các kỳ vọng của khách hàng phù hợp với cam kết thương hiệu của doanh nghiệp.
A23: 1. Trụ cột Khách hàng | B23: Niềm tin của khách hàng | C23: 1.4.2 | D23: Xử lý phản ánh khách hàng | E23: 4 | F23: Nhiều kênh tiếp nhận phản ánh/khiếu nại (trực tiếp, tổng đài, văn bản, email); 100% phản ánh và khiếu nại năm 2025 được tiếp nhận và phối hợp xử lý, có giám sát của Trụ sở chính. | G23: BIDV, Báo cáo thường niên 2025 (bidv.com.vn - Quan hệ nhà đầu tư) | H23: 84-85 | I23: 2025 | J23: Độ tin cậy: Cao. | K23: Khiếu nại nhận được hiếm khi được trả lời hoặc rút kinh nghiệm một cách thích hợp. | L23: Một số khiếu nại nhận được được phản hồi một cách thích hợp và có những cải tiến liên quan. | M23: Hầu hết các khiếu nại nhận được đều được phản hồi một cách thích hợp và dẫn tới các cải tiến liên quan. | N23: Toàn bộ các khiếu nại nhận được đều được phản hồi một cách thích hợp và có sự cải tiến liên tục trong toàn doanh nghiệp. | O23: Toàn bộ các khiếu nại nhận được đều được phản hồi một cách thích hợp và có sự cải tiến liên tục trong toàn doanh nghiệp và các đối tác trong hệ sinh thái của doanh nghiệp.
A24: 1. Trụ cột Khách hàng | B24: Niềm tin của khách hàng | C24: 1.4.3 | D24: Quyền riêng tư | E24: 3 | F24: Cam kết minh bạch thông tin, thông báo chủ động thay đổi phí/lãi suất; theo dõi Luật Bảo vệ dữ liệu cá nhân 2025 (dữ liệu sinh trắc học). | G24: BIDV, Báo cáo thường niên 2025 (bidv.com.vn - Quan hệ nhà đầu tư) | H24: 56-57; 84-85 | I24: 2025 | J24: Độ tin cậy: TB. Chưa công bố chính sách quyền riêng tư của khách hàng trong BCTN. | K24: Khách hàng chưa tin tưởng doanh nghiệp sẽ đảm bảo quyền riêng tư của họ. | L24: Một số khách hàng tin tưởng doanh nghiệp sẽ thiết kế đảm bảo quyền riêng tư của họ. | M24: Hầu hết khách hàng tin tưởng doanh nghiệp sẽ thiết kế đảm bảo quyền riêng tư của họ. | N24: Toàn bộ khách hàng tin tưởng doanh nghiệp sẽ thiết kế đảm bảo quyền riêng tư của họ. | O24: Toàn bộ khách hàng tin tưởng doanh nghiệp và hệ sinh thái của doanh nghiệp sẽ thiết kế đảm bảo quyền riêng tư của họ.
A25: 1. Trụ cột Khách hàng | B25: Niềm tin của khách hàng | C25: 1.4.4 | D25: Kiểm soát thông tin cá nhân, dữ liệu cá nhân | E25: 2 | F25: Công khai Điều kiện, điều khoản chung về xử lý và bảo vệ dữ liệu cá nhân trên website; mẫu Thỏa thuận bảo vệ dữ liệu cá nhân. Chưa thấy công cụ KH tự kiểm soát dữ liệu. | G25: BIDV, Báo cáo phát triển bền vững 2025 | H25: 79 | I25: 2025 | K25: Người dùng chưa thể kiểm soát cách thông tin cá nhân, dữ liệu cá nhân của họ được sử dụng. | L25: Người dùng có thể kiểm soát cách doanh nghiệp sử dụng một số thông tin cá nhân, dữ liệu cá nhân của họ. | M25: Người dùng có thể kiểm soát cách doanh nghiệp sử dụng hầu hết thông tin cá nhân, dữ liệu cá nhân của họ. | N25: Người dùng nhận thức được và có thể dễ dàng kiểm soát cách doanh nghiệp sử dụng tất cả thông tin cá nhân, dữ liệu cá nhân của họ. | O25: Người dùng biết và có thể dễ dàng kiểm soát cách doanh nghiệp và các đối tác trong hệ sinh thái sử dụng tất cả thông tin cá nhân, dữ liệu cá nhân của họ.
A26: 1. Trụ cột Khách hàng | B26: Niềm tin của khách hàng | C26: 1.4.5 | D26: Thúc đẩy niềm tin khách hàng | E26: 3 | F26: Giải Visa 'Ngân hàng an toàn, bảo mật thẻ'; giải ESG 'Ngân hàng có công nghệ ưu việt hỗ trợ quản trị rủi ro bền vững'; BIDV Direct chặn giao dịch nếu chưa định danh sinh trắc học (07/2025); tăng cường cảnh báo gian lận. | G26: BIDV, Báo cáo thường niên 2025 (bidv.com.vn - Quan hệ nhà đầu tư); sggp.org.vn, 'BIDV nỗ lực làm chủ công nghệ để bứt phá tương lai số' (2025) | H26: 14-15; 84-85 | I26: 2025 | J26: Độ tin cậy: TB. | K26: Niềm tin của khách hàng chưa được đưa vào xem xét trong định hướng kinh doanh của doanh nghiệp. | L26: Một số bộ phận, đơn vị chức năng tiến hành kinh doanh theo cách thúc đẩy tạo niềm tin cho khách hàng. | M26: Hầu hết các bộ phận, đơn vị chức năng tiến hành kinh doanh theo cách thúc đẩy vào sự tin tưởng của khách hàng. | N26: Hoạt động kinh doanh được thực hiện bởi doanh nghiệp theo cách tối đa hóa niềm tin của khách hàng. | O26: Hoạt động kinh doanh được thực hiện bởi doanh nghiệp và các đối tác trong hệ sinh thái của doanh nghiệp theo cách tối đa hóa niềm tin của khách hàng.
A27: 2. Trụ cột Chiến lược | B27: Quản lý marketing và thương hiệu | C27: 2.1.1 | D27: Chiến lược thương hiệu | E27: 3 | F27: Áp dụng nhận diện thương hiệu mới (05/03/2025); Top 5 doanh nghiệp giá trị thương hiệu cao nhất VN; truyền thông thương hiệu triển khai đồng bộ. | G27: BIDV, Báo cáo thường niên 2025 (bidv.com.vn - Quan hệ nhà đầu tư) | H27: 20-21; 90-91; 96-97 | I27: 2025 | J27: Độ tin cậy: TB. | K27: Chiến lược thương hiệu số chưa tồn tại hoặc chỉ tồn tại theo sự vụ. | L27: Chiến lược thương hiệu số với nguyên tắc thương hiệu được áp dụng và hiểu tại một số bộ phận, đơn vị chức năng. | M27: Một chiến lược thương hiệu số với nguyên tắc thương hiệu được hiểu và áp dụng bởi hầu hết các bộ phận, đơn vị chức năng. | N27: Một chiến lược thương hiệu số với nguyên tắc thương hiệu được áp dụng và được hiểu trong toàn bộ doanh nghiệp. | O27: Một chiến lược thương hiệu số thống nhất với các nguyên tắc thương hiệu được áp dụng và được hiểu trong toàn bộ doanh nghiệp và các đối tác trong hệ sinh thái của doanh nghiệp.
A28: 2. Trụ cột Chiến lược | B28: Quản lý marketing và thương hiệu | C28: 2.1.2 | D28: Quản trị thương hiệu | E28: 3 | F28: Truyền thông và phát triển thương hiệu triển khai đồng bộ; chỉ số nhận biết thương hiệu tăng một bậc, đứng thứ hai toàn ngành. | G28: BIDV, Báo cáo thường niên 2025 (bidv.com.vn - Quan hệ nhà đầu tư) | H28: 90-91 | I28: 2025 | J28: Độ tin cậy: TB. | K28: Quản trị thương hiệu kỹ thuật số chưa tồn tại hoặc là tồn tại theo sự vụ. | L28: Một số bộ phận, đơn vị chức năng tuân thủ theo các quy tắc được thiết lập trong cấu trúc quản trị. | M28: Hầu hết các bộ phận, đơn vị chức năng tuân thủ các quy tắc được thiết lập trong cấu trúc quản trị. | N28: Toàn bộ doanh nghiệp tuân thủ các quy tắc được thiết lập trong cơ cấu quản trị. | O28: Toàn bộ doanh nghiệp và các đối tác trong hệ sinh thái của doanh nghiệp tuân thủ các quy tắc được thiết lập trong cơ cấu quản trị.
A29: 2. Trụ cột Chiến lược | B29: Quản lý marketing và thương hiệu | C29: 2.1.3 | D29: Chỉ số đo lường thương hiệu | E29: 3 | F29: Theo dõi các chỉ số thương hiệu (nhận biết thương hiệu xếp thứ hai ngành); hơn 40 giải thưởng về thương hiệu, quản trị, chuyển đổi số, chất lượng dịch vụ. | G29: BIDV, Báo cáo thường niên 2025 (bidv.com.vn - Quan hệ nhà đầu tư) | H29: 90-91 | I29: 2025 | J29: Độ tin cậy: TB. | K29: Chỉ số phản ánh hoạt động của thương hiệu số được đo lường theo sự vụ. | L29: Có một quy trình được thực hiện ở một số bộ phận, đơn vị chức năng để đo lường chỉ số phản ánh hoạt động của thương hiệu số. | M29: Có một quy trình được áp dụng trên hầu hết các bộ phận, đơn vị chức năng để đo lường chỉ số phản ánh hoạt động của thương hiệu số. | N29: Có một quy trình hiệu quả trong toàn bộ doanh nghiệp để đo lường chỉ số phản ánh hoạt động của thương hiệu số. | O29: Có một quy trình hiệu quả được áp dụng trong toàn bộ doanh nghiệp và các đối tác trong hệ sinh thái của doanh nghiệp để đo lường chỉ số phản ánh hoạt động của thương hiệu số.
A30: 2. Trụ cột Chiến lược | B30: Quản lý marketing và thương hiệu | C30: 2.1.4 | D30: Chiến lược tiếp thị | E30: 2 | F30: Chiến lược truyền thông khẳng định hình ảnh ngân hàng xanh và thực hành ESG toàn diện (định hướng 2026). | G30: BIDV, Báo cáo thường niên 2025 (bidv.com.vn - Quan hệ nhà đầu tư) | H30: 102-103 | I30: 2025 | J30: Độ tin cậy: Thấp. Chưa có chiến lược tiếp thị số riêng. | K30: Chiến lược tiếp thị số chưa phù hợp với chiến lược tổng thể. | L30: Một số bộ phận, đơn vị chức năng có chiến lược tiếp thị số phù hợp với chiến lược tổng thể. | M30: Hầu hết các bộ phận, đơn vị chức năng đều có chiến lược tiếp thị số phù hợp với chiến lược tổng thể. | N30: Toàn bộ doanh nghiệp có chiến lược tiếp thị số phù hợp với chiến lược tổng thể. | O30: Toàn bộ doanh nghiệp và các đối tác trong hệ sinh thái của doanh nghiệp thống nhất về chiến lược tiếp thị số phù hợp với chiến lược hệ sinh thái tổng thể.
A31: 2. Trụ cột Chiến lược | B31: Quản lý hệ sinh thái | C31: 2.2.1 | D31: Hệ sinh thái kinh doanh | E31: 3 | F31: Chiến lược 2026-2030: tìm động lực tăng trưởng mới cho toàn Hệ sinh thái Tập đoàn BIDV; công ty con, liên doanh (BSC, BIC...); ngân hàng số BIDV Direct cho doanh nghiệp. | G31: BIDV, Báo cáo thường niên 2025 (bidv.com.vn - Quan hệ nhà đầu tư); vnexpress.net, mục Ebank - BIDV ra mắt hệ sinh thái số cho doanh nghiệp (BIDV Direct) | H31: 10-11; 66-71 | I31: 2025 | J31: Độ tin cậy: TB. | K31: Doanh nghiệp chưa nhận thức được giá trị kinh doanh của việc tham gia hệ sinh thái. | L31: Doanh nghiệp thể hiện sự hiểu biết một phần về giá trị của việc tham gia hệ sinh thái và vai trò của doanh nghiệp trong đó. | M31: Doanh nghiệp thể hiện sự hiểu biết đầy đủ về giá trị của việc tham gia hệ sinh thái và vai trò của doanh nghiệp trong đó. | N31: Doanh nghiệp thể hiện sự hiểu biết đầy đủ về giá trị và đã bắt đầu xác định chiến lược tham gia hệ sinh thái và vai trò của doanh nghiệp trong đó. | O31: Doanh nghiệp thể hiện sự hiểu biết đầy đủ về giá trị của việc tham gia hệ sinh thái và đã xác định chiến lược hệ sinh thái và vai trò của doanh nghiệp trong đó.
A32: 2. Trụ cột Chiến lược | B32: Quản lý hệ sinh thái | C32: 2.2.2 | D32: Thiết kế hệ sinh thái | E32: 3 | F32: BIDV Direct: hệ sinh thái số gồm nhiều nền tảng liên kết (tài chính, thương mại, chuỗi cung ứng) thay cho cách quản lý rời rạc; kết nối API với MISA, Cổng dịch vụ công, VSDC. | G32: vnexpress.net, mục Ebank - BIDV ra mắt hệ sinh thái số cho doanh nghiệp (BIDV Direct); thitruongtaichinhtiente.vn, 'BIDV triển khai nhiệm vụ kinh doanh năm 2026' (Etax Mobile, MyShop Pro); vnexpress.net, 'BIDV đẩy mạnh chuyển đổi số' (chiến dịch BIDV Digi Up, 2020) | H32: web | I32: 2026 | J32: Độ tin cậy: TB. | K32: Doanh nghiệp chưa bắt đầu thiết kế hệ sinh thái. | L32: Doanh nghiệp đã bắt đầu thiết kế các hệ sinh thái để thúc đẩy chiến lược của mình. | M32: Doanh nghiệp đã thiết kế các hệ sinh thái để thúc đẩy chiến lược của mình nhằm gia tăng các dòng giá trị hiện có. | N32: Doanh nghiệp đã thiết kế các hệ sinh thái bền vững và mở rộng chiến lược của mình để tập trung vượt ra ngoài lĩnh vực hoạt động, mở ra các luồng giá trị mới. | O32: Doanh nghiệp đã thiết kế các hệ sinh thái bền vững và mở rộng chiến lược của mình bằng cách triển khai các năng lực liên ngành cho phép tạo ra các luồng giá trị mới.
A33: 2. Trụ cột Chiến lược | B33: Quản lý hệ sinh thái | C33: 2.2.3 | D33: Lựa chọn đối tác | E33: 4 | F33: Quan hệ chiến lược BIDV - Hana Bank: Ủy ban Hợp tác chiến lược, Hợp đồng hỗ trợ kỹ thuật 2025-2028, 30 dự án hợp tác; liên doanh bảo hiểm, chứng khoán, thuê tài chính. | G33: BIDV, Báo cáo thường niên 2025 (bidv.com.vn - Quan hệ nhà đầu tư) | H33: 66-71; 90-91; 112-113 | I33: 2025 | J33: Độ tin cậy: Cao. | K33: Doanh nghiệp chưa chọn đối tác như một phần của hệ sinh thái. | L33: Doanh nghiệp đã chọn các đối tác hệ sinh thái để hỗ trợ chiến lược của mình. | M33: Doanh nghiệp đã thiết lập quan hệ đối tác hệ sinh thái đang hỗ trợ chiến lược của mình. | N33: Doanh nghiệp đã thiết lập quan hệ đối tác hệ sinh thái tối ưu nâng cao chiến lược của mình ngoài ngành truyền thống (ngành lĩnh vực đang hoạt động của doanh nghiệp). | O33: Doanh nghiệp đã thiết lập quan hệ đối tác hệ sinh thái tối ưu và triển khai các năng lực liên ngành, tạo điều kiện cho các luồng giá trị mới.
A34: 2. Trụ cột Chiến lược | B34: Bảo trợ tài chính | C34: 2.3.1 | D34: Ngân sách cho chuyển đổi số | E34: 3 | F34: Hạ tầng và an ninh bảo mật được nâng cấp mạnh; tự triển khai 12/16 dự án CNTT trọng điểm, làm lợi hàng nghìn tỷ đồng; 2026 rà soát đầu tư hạ tầng đáp ứng chuẩn Zero Downtime. | G34: BIDV, Báo cáo thường niên 2025 (bidv.com.vn - Quan hệ nhà đầu tư) | H34: 88-89; 98-99; 112-113 | I34: 2025 | J34: Độ tin cậy: TB. Chưa công bố con số ngân sách đầu tư công nghệ. | K34: Doanh nghiệp chưa có ngân sách cho chuyển đổi số. | L34: Ngân sách sẵn có và linh hoạt để chuyển đổi số ở một số bộ phận, đơn vị chức năng. | M34: Ngân sách sẵn có và linh hoạt để chuyển đổi số trên hầu hết các bộ phận, đơn vị chức năng. | N34: Ngân sách luôn sẵn sàng và linh hoạt để chuyển đổi số trên toàn bộ doanh nghiệp. | O34: Ngân sách luôn sẵn sàng và linh hoạt để chuyển đổi số trên toàn bộ doanh nghiệp và các đối tác trong hệ sinh thái của doanh nghiệp.
A35: 2. Trụ cột Chiến lược | B35: Bảo trợ tài chính | C35: 2.3.2 | D35: Đo lường hiệu quả đầu tư | E35: 2 | F35: Số hóa và tiết kiệm chi phí cải thiện CIR (PTBV nêu tác động tối ưu tài chính); hệ thống CNTT 'mang lại giá trị làm lợi to lớn' (chưa định lượng). | G35: BIDV, Báo cáo phát triển bền vững 2025; Báo cáo HĐQT trình ĐHĐCĐ 2026 (bidv.com.vn) | H35: 38; 4 | I35: 2025 | K35: KPI đánh giá các quyết định đầu tư chỉ được thiết lập theo sự vụ. | L35: Một số bộ phận, đơn vị chức năng có sẵn KPIs để đánh giá các quyết định đầu tư. | M35: Hầu hết bộ phận, đơn vị chức năng sử dụng KPIs để đánh giá các quyết định đầu tư. | N35: KPI để đánh giá các quyết định đầu tư được sử dụng trên toàn bộ doanh nghiệp. | O35: KPI để đánh giá các quyết định đầu tư được sử dụng trên toàn bộ doanh nghiệp và các đối tác trong hệ sinh thái của doanh nghiệp.
A36: 2. Trụ cột Chiến lược | B36: Bảo trợ tài chính | C36: 2.3.3 | D36: Đầu tư cải tiến liên tục | E36: 3 | F36: Kế hoạch ứng dụng AI tổng thể 2025-2031 theo danh mục sáng kiến từng Khối/Ban; nâng cấp liên tục Core Banking Profile, Kondor, ALM. | G36: BIDV, Báo cáo thường niên 2025; Báo cáo HĐQT trình ĐHĐCĐ 2026 (bidv.com.vn) | H36: 48-51; 15-16 | I36: 2025 | K36: Quyết định đầu tư chưa được cải thiện dựa trên kết quả trong quá khứ. | L36: Quyết định đầu tư được cải thiện tại một số bộ phận, đơn vị chức năng. | M36: Các quyết định đầu tư liên tục được cải thiện trên hầu hết các bộ phận, đơn vị chức năng. | N36: Các quyết định đầu tư liên tục được cải thiện trong toàn doanh nghiệp. | O36: Các quyết định đầu tư liên tục được cải thiện trong toàn doanh nghiệp và các đối tác trong hệ sinh thái của nó.
A37: 2. Trụ cột Chiến lược | B37: Hiểu biết về thị trường | C37: 2.4.1 | D37: Đánh giá xu hướng ngành | E37: 3 | F37: Định kỳ phân tích môi trường kinh doanh, kinh tế vĩ mô, pháp lý và mức độ cạnh tranh khi nhận diện rủi ro chiến lược. | G37: BIDV, Báo cáo thường niên 2025 (bidv.com.vn - Quan hệ nhà đầu tư) | H37: 52-53 | I37: 2025 | J37: Độ tin cậy: TB. | K37: Đánh giá xu hướng ngành chỉ được thực hiện theo sự vụ. | L37: Một số bộ phận, đơn vị chức năng đánh giá xu hướng ngành để thúc đẩy chiến lược số của họ. | M37: Hầu hết các bộ phận, đơn vị chức năng đánh giá xu hướng ngành để thúc đẩy chiến lược số của họ. | N37: Toàn bộ doanh nghiệp đánh giá xu hướng ngành để thúc đẩy chiến lược số của mình. | O37: Toàn bộ doanh nghiệp và các đối tác trong hệ sinh thái của doanh nghiệp đánh giá xu hướng ngành để thúc đẩy chiến lược số của họ.
A38: 2. Trụ cột Chiến lược | B38: Hiểu biết về thị trường | C38: 2.4.2 | D38: Đánh giá nhu cầu của khách hàng | E38: 3 | F38: Định kỳ phân tích thị trường và nhu cầu khách hàng; nhận diện thách thức cạnh tranh và thay đổi nhu cầu khách hàng, đề xuất điều chỉnh kịp thời. | G38: BIDV, Báo cáo thường niên 2025 (bidv.com.vn - Quan hệ nhà đầu tư) | H38: 52-53 | I38: 2025 | J38: Độ tin cậy: TB. | K38: Phân tích nhu cầu của khách hàng chỉ được thực hiện theo sự vụ. | L38: Một số bộ phận, đơn vị chức năng phân tích nhu cầu của khách hàng để thúc đẩy chiến lược số của họ. | M38: Hầu hết các bộ phận, đơn vị chức năng phân tích nhu cầu của khách hàng để thúc đẩy chiến lược số của họ. | N38: Toàn bộ doanh nghiệp phân tích và dự đoán nhu cầu của khách hàng để thúc đẩy chiến lược số của mình. | O38: Toàn bộ doanh nghiệp và các đối tác trong hệ sinh thái của mình phân tích và dự đoán nhu cầu của khách hàng để thúc đẩy chiến lược số của họ.
A39: 2. Trụ cột Chiến lược | B39: Hiểu biết về thị trường | C39: 2.4.3 | D39: Đánh giá mạng lưới giá trị | E39: N/A | F39: Không tìm thấy thông tin công khai. | K39: Đánh giá kết cấu giá trị chỉ được thực hiện theo sự vụ. | L39: Một số bộ phận, đơn vị chức năng phân tích mạng lưới giá trị để thúc đẩy chiến lược số của họ. | M39: Hầu hết các bộ phận, đơn vị chức năng phân tích mạng lưới giá trị để thúc đẩy chiến lược số của họ. | N39: Toàn bộ doanh nghiệp phân tích và dự đoán mạng lưới giá trị để thúc đẩy chiến lược số của mình. | O39: Toàn bộ doanh nghiệp và các đối tác trong hệ sinh thái của doanh nghiệp phân tích và dự đoán mạng lưới giá trị để thúc đẩy chiến lược số của họ.
A40: 2. Trụ cột Chiến lược | B40: Quản lý danh mục sản phẩm, dịch vụ số | C40: 2.5.1 | D40: Cân đối danh mục sản phẩm và dịch vụ | E40: 3 | F40: Chuyển dịch cơ cấu tín dụng; dư nợ bán lẻ, FDI, xanh (82.300 tỷ đồng dư nợ xanh); tái cơ cấu danh mục tài sản nợ năm 2026. | G40: BIDV, Báo cáo thường niên 2025 (bidv.com.vn - Quan hệ nhà đầu tư) | H40: 88-91; 100-101 | I40: 2025 | J40: Độ tin cậy: TB. | K40: Cân bằng danh mục đầu tư chỉ được thực hiện theo sự vụ. | L40: Một số bộ phận, đơn vị chức năng có danh mục sản phẩm và dịch vụ số phù hợp một phần với chiến lược của doanh nghiệp. | M40: Hầu hết các bộ phận, đơn vị chức năng đều có danh mục sản phẩm và dịch vụ số cân bằng, phù hợp nhất với chiến lược của doanh nghiệp. | N40: Toàn bộ doanh nghiệp có một danh mục sản phẩm và dịch vụ số cân bằng phù hợp nhất với chiến lược của mình. | O40: Toàn bộ doanh nghiệp và các đối tác trong hệ sinh thái của doanh nghiệp có một danh mục sản phẩm và dịch vụ số cân bằng, phù hợp nhất với chiến lược chung của mình.
...
